[2025-06-29T18:39:30.762+0000] {taskinstance.py:1956} INFO - Dependencies all met for dep_context=non-requeueable deps ti=<TaskInstance: superstore_etl_workflow.cargar_dim_producto manual__2025-06-29T18:39:27.370792+00:00 [queued]>
[2025-06-29T18:39:30.779+0000] {taskinstance.py:1956} INFO - Dependencies all met for dep_context=requeueable deps ti=<TaskInstance: superstore_etl_workflow.cargar_dim_producto manual__2025-06-29T18:39:27.370792+00:00 [queued]>
[2025-06-29T18:39:30.780+0000] {taskinstance.py:2170} INFO - Starting attempt 1 of 2
[2025-06-29T18:39:30.813+0000] {taskinstance.py:2191} INFO - Executing <Task(PythonOperator): cargar_dim_producto> on 2025-06-29 18:39:27.370792+00:00
[2025-06-29T18:39:30.824+0000] {standard_task_runner.py:60} INFO - Started process 197 to run task
[2025-06-29T18:39:30.845+0000] {standard_task_runner.py:87} INFO - Running: ['***', 'tasks', 'run', 'superstore_etl_workflow', 'cargar_dim_producto', 'manual__2025-06-29T18:39:27.370792+00:00', '--job-id', '2', '--raw', '--subdir', 'DAGS_FOLDER/superstore_etl_dag.py', '--cfg-path', '/tmp/tmp7419bpzk']
[2025-06-29T18:39:30.850+0000] {standard_task_runner.py:88} INFO - Job 2: Subtask cargar_dim_producto
[2025-06-29T18:39:31.074+0000] {task_command.py:423} INFO - Running <TaskInstance: superstore_etl_workflow.cargar_dim_producto manual__2025-06-29T18:39:27.370792+00:00 [running]> on host b2a8009b754b
[2025-06-29T18:39:31.401+0000] {taskinstance.py:2480} INFO - Exporting env vars: AIRFLOW_CTX_DAG_OWNER='tu_nombre' AIRFLOW_CTX_DAG_ID='superstore_etl_workflow' AIRFLOW_CTX_TASK_ID='cargar_dim_producto' AIRFLOW_CTX_EXECUTION_DATE='2025-06-29T18:39:27.370792+00:00' AIRFLOW_CTX_TRY_NUMBER='1' AIRFLOW_CTX_DAG_RUN_ID='manual__2025-06-29T18:39:27.370792+00:00'
[2025-06-29T18:39:31.408+0000] {logging_mixin.py:188} INFO - Iniciando extracci√≥n de Global_Superstore2.csv desde GCS...
[2025-06-29T18:39:31.420+0000] {taskinstance.py:2698} ERROR - Task failed with exception
Traceback (most recent call last):
  File "/home/airflow/.local/lib/python3.8/site-packages/airflow/models/taskinstance.py", line 433, in _execute_task
    result = execute_callable(context=context, **execute_callable_kwargs)
  File "/home/airflow/.local/lib/python3.8/site-packages/airflow/operators/python.py", line 199, in execute
    return_value = self.execute_callable()
  File "/home/airflow/.local/lib/python3.8/site-packages/airflow/operators/python.py", line 216, in execute_callable
    return self.python_callable(*self.op_args, **self.op_kwargs)
  File "/opt/airflow/dags/superstore_etl_dag.py", line 33, in etl_dim_producto
    storage_client = storage.Client(project=GCP_PROJECT_ID)
  File "/home/airflow/.local/lib/python3.8/site-packages/google/cloud/storage/client.py", line 172, in __init__
    super(Client, self).__init__(
  File "/home/airflow/.local/lib/python3.8/site-packages/google/cloud/client/__init__.py", line 321, in __init__
    Client.__init__(
  File "/home/airflow/.local/lib/python3.8/site-packages/google/cloud/client/__init__.py", line 178, in __init__
    credentials, _ = google.auth.default(scopes=scopes)
  File "/home/airflow/.local/lib/python3.8/site-packages/google/auth/_default.py", line 657, in default
    credentials, project_id = checker()
  File "/home/airflow/.local/lib/python3.8/site-packages/google/auth/_default.py", line 650, in <lambda>
    lambda: _get_explicit_environ_credentials(quota_project_id=quota_project_id),
  File "/home/airflow/.local/lib/python3.8/site-packages/google/auth/_default.py", line 270, in _get_explicit_environ_credentials
    credentials, project_id = load_credentials_from_file(
  File "/home/airflow/.local/lib/python3.8/site-packages/google/auth/_default.py", line 118, in load_credentials_from_file
    with io.open(filename, "r") as file_obj:
IsADirectoryError: [Errno 21] Is a directory: '/opt/airflow/gcp_credentials.json'
[2025-06-29T18:39:31.463+0000] {taskinstance.py:1138} INFO - Marking task as UP_FOR_RETRY. dag_id=superstore_etl_workflow, task_id=cargar_dim_producto, execution_date=20250629T183927, start_date=20250629T183930, end_date=20250629T183931
[2025-06-29T18:39:31.493+0000] {standard_task_runner.py:107} ERROR - Failed to execute job 2 for task cargar_dim_producto ([Errno 21] Is a directory: '/opt/airflow/gcp_credentials.json'; 197)
[2025-06-29T18:39:31.537+0000] {local_task_job_runner.py:234} INFO - Task exited with return code 1
[2025-06-29T18:39:31.695+0000] {taskinstance.py:3280} INFO - 0 downstream tasks scheduled from follow-on schedule check
