[2025-06-29T19:46:24.679+0000] {taskinstance.py:1956} INFO - Dependencies all met for dep_context=non-requeueable deps ti=<TaskInstance: superstore_etl_workflow.cargar_dim_producto manual__2025-06-29T19:41:16.004045+00:00 [queued]>
[2025-06-29T19:46:24.689+0000] {taskinstance.py:1956} INFO - Dependencies all met for dep_context=requeueable deps ti=<TaskInstance: superstore_etl_workflow.cargar_dim_producto manual__2025-06-29T19:41:16.004045+00:00 [queued]>
[2025-06-29T19:46:24.690+0000] {taskinstance.py:2170} INFO - Starting attempt 2 of 2
[2025-06-29T19:46:24.706+0000] {taskinstance.py:2191} INFO - Executing <Task(PythonOperator): cargar_dim_producto> on 2025-06-29 19:41:16.004045+00:00
[2025-06-29T19:46:24.712+0000] {standard_task_runner.py:60} INFO - Started process 250 to run task
[2025-06-29T19:46:24.717+0000] {standard_task_runner.py:87} INFO - Running: ['***', 'tasks', 'run', 'superstore_etl_workflow', 'cargar_dim_producto', 'manual__2025-06-29T19:41:16.004045+00:00', '--job-id', '14', '--raw', '--subdir', 'DAGS_FOLDER/superstore_etl_dag.py', '--cfg-path', '/tmp/tmp2w1g_7j6']
[2025-06-29T19:46:24.720+0000] {standard_task_runner.py:88} INFO - Job 14: Subtask cargar_dim_producto
[2025-06-29T19:46:24.781+0000] {task_command.py:423} INFO - Running <TaskInstance: superstore_etl_workflow.cargar_dim_producto manual__2025-06-29T19:41:16.004045+00:00 [running]> on host 85c12c2be069
[2025-06-29T19:46:24.871+0000] {taskinstance.py:2480} INFO - Exporting env vars: AIRFLOW_CTX_DAG_OWNER='tu_nombre' AIRFLOW_CTX_DAG_ID='superstore_etl_workflow' AIRFLOW_CTX_TASK_ID='cargar_dim_producto' AIRFLOW_CTX_EXECUTION_DATE='2025-06-29T19:41:16.004045+00:00' AIRFLOW_CTX_TRY_NUMBER='2' AIRFLOW_CTX_DAG_RUN_ID='manual__2025-06-29T19:41:16.004045+00:00'
[2025-06-29T19:46:24.872+0000] {logging_mixin.py:188} INFO - Iniciando ETL para la dimensi√≥n de productos desde Global_Superstore2.csv...
[2025-06-29T19:46:25.743+0000] {logging_mixin.py:188} INFO - Error al leer el archivo de GCS: 403 GET https://storage.googleapis.com/download/storage/v1/b/at-bucket-practica-sistemas/o/Global_Superstore2.csv?alt=media: ***-superstore-worker@tarea-sistemas-proceso-etl.iam.gserviceaccount.com does not have storage.objects.get access to the Google Cloud Storage object. Permission &#39;storage.objects.get&#39; denied on resource (or it may not exist).: ('Request failed with status code', 403, 'Expected one of', <HTTPStatus.OK: 200>, <HTTPStatus.PARTIAL_CONTENT: 206>)
[2025-06-29T19:46:25.744+0000] {taskinstance.py:2698} ERROR - Task failed with exception
Traceback (most recent call last):
  File "/home/airflow/.local/lib/python3.8/site-packages/google/cloud/storage/blob.py", line 4332, in _prep_and_do_download
    self._do_download(
  File "/home/airflow/.local/lib/python3.8/site-packages/google/cloud/storage/blob.py", line 987, in _do_download
    response = download.consume(transport, timeout=timeout)
  File "/home/airflow/.local/lib/python3.8/site-packages/google/resumable_media/requests/download.py", line 237, in consume
    return _request_helpers.wait_and_retry(
  File "/home/airflow/.local/lib/python3.8/site-packages/google/resumable_media/requests/_request_helpers.py", line 155, in wait_and_retry
    response = func()
  File "/home/airflow/.local/lib/python3.8/site-packages/google/resumable_media/requests/download.py", line 219, in retriable_request
    self._process_response(result)
  File "/home/airflow/.local/lib/python3.8/site-packages/google/resumable_media/_download.py", line 188, in _process_response
    _helpers.require_status_code(
  File "/home/airflow/.local/lib/python3.8/site-packages/google/resumable_media/_helpers.py", line 108, in require_status_code
    raise common.InvalidResponse(
google.resumable_media.common.InvalidResponse: ('Request failed with status code', 403, 'Expected one of', 200, 206)

During handling of the above exception, another exception occurred:

Traceback (most recent call last):
  File "/home/airflow/.local/lib/python3.8/site-packages/airflow/models/taskinstance.py", line 433, in _execute_task
    result = execute_callable(context=context, **execute_callable_kwargs)
  File "/home/airflow/.local/lib/python3.8/site-packages/airflow/operators/python.py", line 199, in execute
    return_value = self.execute_callable()
  File "/home/airflow/.local/lib/python3.8/site-packages/airflow/operators/python.py", line 216, in execute_callable
    return self.python_callable(*self.op_args, **self.op_kwargs)
  File "/opt/airflow/dags/superstore_etl_dag.py", line 40, in etl_dim_producto
    content = blob.download_as_string().decode('utf-8')
  File "/home/airflow/.local/lib/python3.8/site-packages/google/cloud/storage/blob.py", line 1520, in download_as_string
    return self.download_as_bytes(
  File "/home/airflow/.local/lib/python3.8/site-packages/google/cloud/storage/blob.py", line 1405, in download_as_bytes
    self._prep_and_do_download(
  File "/home/airflow/.local/lib/python3.8/site-packages/google/cloud/storage/blob.py", line 4345, in _prep_and_do_download
    _raise_from_invalid_response(exc)
  File "/home/airflow/.local/lib/python3.8/site-packages/google/cloud/storage/blob.py", line 4791, in _raise_from_invalid_response
    raise exceptions.from_http_status(response.status_code, message, response=response)
google.api_core.exceptions.Forbidden: 403 GET https://storage.googleapis.com/download/storage/v1/b/at-bucket-practica-sistemas/o/Global_Superstore2.csv?alt=media: airflow-superstore-worker@tarea-sistemas-proceso-etl.iam.gserviceaccount.com does not have storage.objects.get access to the Google Cloud Storage object. Permission &#39;storage.objects.get&#39; denied on resource (or it may not exist).: ('Request failed with status code', 403, 'Expected one of', <HTTPStatus.OK: 200>, <HTTPStatus.PARTIAL_CONTENT: 206>)
[2025-06-29T19:46:25.764+0000] {taskinstance.py:1138} INFO - Marking task as FAILED. dag_id=superstore_etl_workflow, task_id=cargar_dim_producto, execution_date=20250629T194116, start_date=20250629T194624, end_date=20250629T194625
[2025-06-29T19:46:25.786+0000] {standard_task_runner.py:107} ERROR - Failed to execute job 14 for task cargar_dim_producto (403 GET https://storage.googleapis.com/download/storage/v1/b/at-bucket-practica-sistemas/o/Global_Superstore2.csv?alt=media: airflow-superstore-worker@tarea-sistemas-proceso-etl.iam.gserviceaccount.com does not have storage.objects.get access to the Google Cloud Storage object. Permission &#39;storage.objects.get&#39; denied on resource (or it may not exist).: ('Request failed with status code', 403, 'Expected one of', <HTTPStatus.OK: 200>, <HTTPStatus.PARTIAL_CONTENT: 206>); 250)
[2025-06-29T19:46:25.818+0000] {local_task_job_runner.py:234} INFO - Task exited with return code 1
[2025-06-29T19:46:25.863+0000] {taskinstance.py:3280} INFO - 0 downstream tasks scheduled from follow-on schedule check
